Loaded data, total number of samples: 8000
Loaded data, total number of samples: 2000
Outputting loss every 100 batches
Validating every 500 batches
Starting Epoch 0
  0% 0/32 [00:00<?, ?it/s][34m[1mwandb[39m[22m: Currently logged in as: [33mvicentevivan[39m. Use [1m`wandb login --relogin`[22m to force relogin
Traceback (most recent call last):
  File "/Users/vicentevivanco/opt/anaconda3/lib/python3.9/site-packages/wandb/sdk/wandb_init.py", line 999, in init
    run = wi.init()
  File "/Users/vicentevivanco/opt/anaconda3/lib/python3.9/site-packages/wandb/sdk/wandb_init.py", line 523, in init
    backend.ensure_launched()
  File "/Users/vicentevivanco/opt/anaconda3/lib/python3.9/site-packages/wandb/sdk/backend/backend.py", line 220, in ensure_launched
    self.wandb_process.start()
  File "/Users/vicentevivanco/opt/anaconda3/lib/python3.9/multiprocessing/process.py", line 121, in start
    self._popen = self._Popen(self)
  File "/Users/vicentevivanco/opt/anaconda3/lib/python3.9/multiprocessing/context.py", line 284, in _Popen
    return Popen(process_obj)
  File "/Users/vicentevivanco/opt/anaconda3/lib/python3.9/multiprocessing/popen_spawn_posix.py", line 32, in __init__
    super().__init__(process_obj)
  File "/Users/vicentevivanco/opt/anaconda3/lib/python3.9/multiprocessing/popen_fork.py", line 19, in __init__
    self._launch(process_obj)
  File "/Users/vicentevivanco/opt/anaconda3/lib/python3.9/multiprocessing/popen_spawn_posix.py", line 42, in _launch
    prep_data = spawn.get_preparation_data(process_obj._name)
  File "/Users/vicentevivanco/opt/anaconda3/lib/python3.9/multiprocessing/spawn.py", line 154, in get_preparation_data
    _check_not_importing_main()
  File "/Users/vicentevivanco/opt/anaconda3/lib/python3.9/multiprocessing/spawn.py", line 134, in _check_not_importing_main
    raise RuntimeError('''
RuntimeError:
        An attempt has been made to start a new process before the
        current process has finished its bootstrapping phase.
        This probably means that you are not using fork to start your
        child processes and you have forgotten to use the proper idiom
        in the main module:
            if __name__ == '__main__':
                freeze_support()
                ...
        The "freeze_support()" line can be omitted if the program
        is not going to be frozen to produce an executable.
[34m[1mwandb[39m[22m: Currently logged in as: [33mvicentevivan[39m. Use [1m`wandb login --relogin`[22m to force relogin
[34m[1mwandb[39m[22m: Currently logged in as: [33mvicentevivan[39m. Use [1m`wandb login --relogin`[22m to force relogin
[34m[1mwandb[39m[22m: Currently logged in as: [33mvicentevivan[39m. Use [1m`wandb login --relogin`[22m to force relogin
[34m[1mwandb[39m[22m: Currently logged in as: [33mvicentevivan[39m. Use [1m`wandb login --relogin`[22m to force relogin
Traceback (most recent call last):
  File "/Users/vicentevivanco/opt/anaconda3/lib/python3.9/site-packages/wandb/sdk/wandb_init.py", line 999, in init
    run = wi.init()
  File "/Users/vicentevivanco/opt/anaconda3/lib/python3.9/site-packages/wandb/sdk/wandb_init.py", line 523, in init
    backend.ensure_launched()
  File "/Users/vicentevivanco/opt/anaconda3/lib/python3.9/site-packages/wandb/sdk/backend/backend.py", line 220, in ensure_launched
    self.wandb_process.start()
  File "/Users/vicentevivanco/opt/anaconda3/lib/python3.9/multiprocessing/process.py", line 121, in start
    self._popen = self._Popen(self)
  File "/Users/vicentevivanco/opt/anaconda3/lib/python3.9/multiprocessing/context.py", line 284, in _Popen
    return Popen(process_obj)
  File "/Users/vicentevivanco/opt/anaconda3/lib/python3.9/multiprocessing/popen_spawn_posix.py", line 32, in __init__
    super().__init__(process_obj)
  File "/Users/vicentevivanco/opt/anaconda3/lib/python3.9/multiprocessing/popen_fork.py", line 19, in __init__
    self._launch(process_obj)
  File "/Users/vicentevivanco/opt/anaconda3/lib/python3.9/multiprocessing/popen_spawn_posix.py", line 42, in _launch
    prep_data = spawn.get_preparation_data(process_obj._name)
  File "/Users/vicentevivanco/opt/anaconda3/lib/python3.9/multiprocessing/spawn.py", line 154, in get_preparation_data
    _check_not_importing_main()
  File "/Users/vicentevivanco/opt/anaconda3/lib/python3.9/multiprocessing/spawn.py", line 134, in _check_not_importing_main
    raise RuntimeError('''
RuntimeError:
        An attempt has been made to start a new process before the
        current process has finished its bootstrapping phase.
        This probably means that you are not using fork to start your
        child processes and you have forgotten to use the proper idiom
        in the main module:
            if __name__ == '__main__':
                freeze_support()
                ...
        The "freeze_support()" line can be omitted if the program
        is not going to be frozen to produce an executable.
Traceback (most recent call last):
  File "/Users/vicentevivanco/opt/anaconda3/lib/python3.9/site-packages/wandb/sdk/wandb_init.py", line 999, in init
    run = wi.init()
  File "/Users/vicentevivanco/opt/anaconda3/lib/python3.9/site-packages/wandb/sdk/wandb_init.py", line 523, in init
    backend.ensure_launched()
  File "/Users/vicentevivanco/opt/anaconda3/lib/python3.9/site-packages/wandb/sdk/backend/backend.py", line 220, in ensure_launched
    self.wandb_process.start()
  File "/Users/vicentevivanco/opt/anaconda3/lib/python3.9/multiprocessing/process.py", line 121, in start
    self._popen = self._Popen(self)
  File "/Users/vicentevivanco/opt/anaconda3/lib/python3.9/multiprocessing/context.py", line 284, in _Popen
    return Popen(process_obj)
  File "/Users/vicentevivanco/opt/anaconda3/lib/python3.9/multiprocessing/popen_spawn_posix.py", line 32, in __init__
    super().__init__(process_obj)
  File "/Users/vicentevivanco/opt/anaconda3/lib/python3.9/multiprocessing/popen_fork.py", line 19, in __init__
    self._launch(process_obj)
  File "/Users/vicentevivanco/opt/anaconda3/lib/python3.9/multiprocessing/popen_spawn_posix.py", line 42, in _launch
    prep_data = spawn.get_preparation_data(process_obj._name)
  File "/Users/vicentevivanco/opt/anaconda3/lib/python3.9/multiprocessing/spawn.py", line 154, in get_preparation_data
    _check_not_importing_main()
  File "/Users/vicentevivanco/opt/anaconda3/lib/python3.9/multiprocessing/spawn.py", line 134, in _check_not_importing_main
    raise RuntimeError('''
RuntimeError:
        An attempt has been made to start a new process before the
        current process has finished its bootstrapping phase.
        This probably means that you are not using fork to start your
        child processes and you have forgotten to use the proper idiom
        in the main module:
            if __name__ == '__main__':
                freeze_support()
                ...
        The "freeze_support()" line can be omitted if the program
        is not going to be frozen to produce an executable.
Traceback (most recent call last):
  File "/Users/vicentevivanco/opt/anaconda3/lib/python3.9/site-packages/wandb/sdk/wandb_init.py", line 999, in init
    run = wi.init()
  File "/Users/vicentevivanco/opt/anaconda3/lib/python3.9/site-packages/wandb/sdk/wandb_init.py", line 523, in init
    backend.ensure_launched()
  File "/Users/vicentevivanco/opt/anaconda3/lib/python3.9/site-packages/wandb/sdk/backend/backend.py", line 220, in ensure_launched
    self.wandb_process.start()
  File "/Users/vicentevivanco/opt/anaconda3/lib/python3.9/multiprocessing/process.py", line 121, in start
    self._popen = self._Popen(self)
  File "/Users/vicentevivanco/opt/anaconda3/lib/python3.9/multiprocessing/context.py", line 284, in _Popen
    return Popen(process_obj)
  File "/Users/vicentevivanco/opt/anaconda3/lib/python3.9/multiprocessing/popen_spawn_posix.py", line 32, in __init__
    super().__init__(process_obj)
  File "/Users/vicentevivanco/opt/anaconda3/lib/python3.9/multiprocessing/popen_fork.py", line 19, in __init__
    self._launch(process_obj)
  File "/Users/vicentevivanco/opt/anaconda3/lib/python3.9/multiprocessing/popen_spawn_posix.py", line 42, in _launch
    prep_data = spawn.get_preparation_data(process_obj._name)
  File "/Users/vicentevivanco/opt/anaconda3/lib/python3.9/multiprocessing/spawn.py", line 154, in get_preparation_data
    _check_not_importing_main()
  File "/Users/vicentevivanco/opt/anaconda3/lib/python3.9/multiprocessing/spawn.py", line 134, in _check_not_importing_main
    raise RuntimeError('''
RuntimeError:
        An attempt has been made to start a new process before the
        current process has finished its bootstrapping phase.
        This probably means that you are not using fork to start your
        child processes and you have forgotten to use the proper idiom
        in the main module:
            if __name__ == '__main__':
                freeze_support()
                ...
        The "freeze_support()" line can be omitted if the program
        is not going to be frozen to produce an executable.
Traceback (most recent call last):
  File "/Users/vicentevivanco/opt/anaconda3/lib/python3.9/site-packages/wandb/sdk/wandb_init.py", line 999, in init
    run = wi.init()
  File "/Users/vicentevivanco/opt/anaconda3/lib/python3.9/site-packages/wandb/sdk/wandb_init.py", line 523, in init
    backend.ensure_launched()
  File "/Users/vicentevivanco/opt/anaconda3/lib/python3.9/site-packages/wandb/sdk/backend/backend.py", line 220, in ensure_launched
    self.wandb_process.start()
  File "/Users/vicentevivanco/opt/anaconda3/lib/python3.9/multiprocessing/process.py", line 121, in start
    self._popen = self._Popen(self)
  File "/Users/vicentevivanco/opt/anaconda3/lib/python3.9/multiprocessing/context.py", line 284, in _Popen
    return Popen(process_obj)
  File "/Users/vicentevivanco/opt/anaconda3/lib/python3.9/multiprocessing/popen_spawn_posix.py", line 32, in __init__
    super().__init__(process_obj)
  File "/Users/vicentevivanco/opt/anaconda3/lib/python3.9/multiprocessing/popen_fork.py", line 19, in __init__
    self._launch(process_obj)
  File "/Users/vicentevivanco/opt/anaconda3/lib/python3.9/multiprocessing/popen_spawn_posix.py", line 42, in _launch
    prep_data = spawn.get_preparation_data(process_obj._name)
  File "/Users/vicentevivanco/opt/anaconda3/lib/python3.9/multiprocessing/spawn.py", line 154, in get_preparation_data
    _check_not_importing_main()
  File "/Users/vicentevivanco/opt/anaconda3/lib/python3.9/multiprocessing/spawn.py", line 134, in _check_not_importing_main
    raise RuntimeError('''
RuntimeError:
        An attempt has been made to start a new process before the
        current process has finished its bootstrapping phase.
        This probably means that you are not using fork to start your
        child processes and you have forgotten to use the proper idiom
        in the main module:
            if __name__ == '__main__':
                freeze_support()
                ...
        The "freeze_support()" line can be omitted if the program
        is not going to be frozen to produce an executable.
[34m[1mwandb[39m[22m: Currently logged in as: [33mvicentevivan[39m. Use [1m`wandb login --relogin`[22m to force relogin
Traceback (most recent call last):
[34m[1mwandb[39m[22m: Currently logged in as: [33mvicentevivan[39m. Use [1m`wandb login --relogin`[22m to force relogin
  File "/Users/vicentevivanco/opt/anaconda3/lib/python3.9/site-packages/wandb/sdk/wandb_init.py", line 999, in init
    run = wi.init()
  File "/Users/vicentevivanco/opt/anaconda3/lib/python3.9/site-packages/wandb/sdk/wandb_init.py", line 523, in init
    backend.ensure_launched()
  File "/Users/vicentevivanco/opt/anaconda3/lib/python3.9/site-packages/wandb/sdk/backend/backend.py", line 220, in ensure_launched
    self.wandb_process.start()
  File "/Users/vicentevivanco/opt/anaconda3/lib/python3.9/multiprocessing/process.py", line 121, in start
    self._popen = self._Popen(self)
  File "/Users/vicentevivanco/opt/anaconda3/lib/python3.9/multiprocessing/context.py", line 284, in _Popen
    return Popen(process_obj)
  File "/Users/vicentevivanco/opt/anaconda3/lib/python3.9/multiprocessing/popen_spawn_posix.py", line 32, in __init__
    super().__init__(process_obj)
  File "/Users/vicentevivanco/opt/anaconda3/lib/python3.9/multiprocessing/popen_fork.py", line 19, in __init__
    self._launch(process_obj)
  File "/Users/vicentevivanco/opt/anaconda3/lib/python3.9/multiprocessing/popen_spawn_posix.py", line 42, in _launch
    prep_data = spawn.get_preparation_data(process_obj._name)
  File "/Users/vicentevivanco/opt/anaconda3/lib/python3.9/multiprocessing/spawn.py", line 154, in get_preparation_data
    _check_not_importing_main()
  File "/Users/vicentevivanco/opt/anaconda3/lib/python3.9/multiprocessing/spawn.py", line 134, in _check_not_importing_main
    raise RuntimeError('''
RuntimeError:
        An attempt has been made to start a new process before the
        current process has finished its bootstrapping phase.
        This probably means that you are not using fork to start your
        child processes and you have forgotten to use the proper idiom
        in the main module:
            if __name__ == '__main__':
                freeze_support()
                ...
        The "freeze_support()" line can be omitted if the program
        is not going to be frozen to produce an executable.
Traceback (most recent call last):
  File "/Users/vicentevivanco/opt/anaconda3/lib/python3.9/site-packages/wandb/sdk/wandb_init.py", line 999, in init
    run = wi.init()
  File "/Users/vicentevivanco/opt/anaconda3/lib/python3.9/site-packages/wandb/sdk/wandb_init.py", line 523, in init
    backend.ensure_launched()
  File "/Users/vicentevivanco/opt/anaconda3/lib/python3.9/site-packages/wandb/sdk/backend/backend.py", line 220, in ensure_launched
    self.wandb_process.start()
  File "/Users/vicentevivanco/opt/anaconda3/lib/python3.9/multiprocessing/process.py", line 121, in start
    self._popen = self._Popen(self)
  File "/Users/vicentevivanco/opt/anaconda3/lib/python3.9/multiprocessing/context.py", line 284, in _Popen
    return Popen(process_obj)
  File "/Users/vicentevivanco/opt/anaconda3/lib/python3.9/multiprocessing/popen_spawn_posix.py", line 32, in __init__
    super().__init__(process_obj)
  File "/Users/vicentevivanco/opt/anaconda3/lib/python3.9/multiprocessing/popen_fork.py", line 19, in __init__
    self._launch(process_obj)
  File "/Users/vicentevivanco/opt/anaconda3/lib/python3.9/multiprocessing/popen_spawn_posix.py", line 42, in _launch
    prep_data = spawn.get_preparation_data(process_obj._name)
  File "/Users/vicentevivanco/opt/anaconda3/lib/python3.9/multiprocessing/spawn.py", line 154, in get_preparation_data
    _check_not_importing_main()
  File "/Users/vicentevivanco/opt/anaconda3/lib/python3.9/multiprocessing/spawn.py", line 134, in _check_not_importing_main
    raise RuntimeError('''
RuntimeError:
        An attempt has been made to start a new process before the
        current process has finished its bootstrapping phase.
        This probably means that you are not using fork to start your
        child processes and you have forgotten to use the proper idiom
        in the main module:
            if __name__ == '__main__':
                freeze_support()
                ...
        The "freeze_support()" line can be omitted if the program
        is not going to be frozen to produce an executable.
[34m[1mwandb[39m[22m: Currently logged in as: [33mvicentevivan[39m. Use [1m`wandb login --relogin`[22m to force relogin
Traceback (most recent call last):
  File "/Users/vicentevivanco/opt/anaconda3/lib/python3.9/site-packages/wandb/sdk/wandb_init.py", line 999, in init
    run = wi.init()
  File "/Users/vicentevivanco/opt/anaconda3/lib/python3.9/site-packages/wandb/sdk/wandb_init.py", line 523, in init
    backend.ensure_launched()
  File "/Users/vicentevivanco/opt/anaconda3/lib/python3.9/site-packages/wandb/sdk/backend/backend.py", line 220, in ensure_launched
    self.wandb_process.start()
  File "/Users/vicentevivanco/opt/anaconda3/lib/python3.9/multiprocessing/process.py", line 121, in start
    self._popen = self._Popen(self)
  File "/Users/vicentevivanco/opt/anaconda3/lib/python3.9/multiprocessing/context.py", line 284, in _Popen
    return Popen(process_obj)
  File "/Users/vicentevivanco/opt/anaconda3/lib/python3.9/multiprocessing/popen_spawn_posix.py", line 32, in __init__
    super().__init__(process_obj)
  File "/Users/vicentevivanco/opt/anaconda3/lib/python3.9/multiprocessing/popen_fork.py", line 19, in __init__
    self._launch(process_obj)
  File "/Users/vicentevivanco/opt/anaconda3/lib/python3.9/multiprocessing/popen_spawn_posix.py", line 42, in _launch
    prep_data = spawn.get_preparation_data(process_obj._name)
  File "/Users/vicentevivanco/opt/anaconda3/lib/python3.9/multiprocessing/spawn.py", line 154, in get_preparation_data
    _check_not_importing_main()
  File "/Users/vicentevivanco/opt/anaconda3/lib/python3.9/multiprocessing/spawn.py", line 134, in _check_not_importing_main
    raise RuntimeError('''
RuntimeError:
        An attempt has been made to start a new process before the
        current process has finished its bootstrapping phase.
        This probably means that you are not using fork to start your
        child processes and you have forgotten to use the proper idiom
        in the main module:
            if __name__ == '__main__':
                freeze_support()
                ...
        The "freeze_support()" line can be omitted if the program
        is not going to be frozen to produce an executable.
Problem at: /Users/vicentevivanco/Desktop/Research/Mathematics/NNs/main.py 24 <module>
Problem at: /Users/vicentevivanco/Desktop/Research/Mathematics/NNs/main.py 24 <module>
Problem at: /Users/vicentevivanco/Desktop/Research/Mathematics/NNs/main.py 24 <module>
Problem at: /Users/vicentevivanco/Desktop/Research/Mathematics/NNs/main.py 24 <module>
Problem at: /Users/vicentevivanco/Desktop/Research/Mathematics/NNs/main.py 24 <module>
Problem at: /Users/vicentevivanco/Desktop/Research/Mathematics/NNs/main.py 24 <module>
Problem at: /Users/vicentevivanco/Desktop/Research/Mathematics/NNs/main.py 24 <module>
Problem at: /Users/vicentevivanco/Desktop/Research/Mathematics/NNs/main.py 24 <module>
[34m[1mwandb[39m[22m: [32m[41mERROR[39m[49m Abnormal program exit
Traceback (most recent call last):
  File "/Users/vicentevivanco/opt/anaconda3/lib/python3.9/site-packages/wandb/sdk/wandb_init.py", line 999, in init
    run = wi.init()
  File "/Users/vicentevivanco/opt/anaconda3/lib/python3.9/site-packages/wandb/sdk/wandb_init.py", line 523, in init
    backend.ensure_launched()
  File "/Users/vicentevivanco/opt/anaconda3/lib/python3.9/site-packages/wandb/sdk/backend/backend.py", line 220, in ensure_launched
    self.wandb_process.start()
  File "/Users/vicentevivanco/opt/anaconda3/lib/python3.9/multiprocessing/process.py", line 121, in start
    self._popen = self._Popen(self)
  File "/Users/vicentevivanco/opt/anaconda3/lib/python3.9/multiprocessing/context.py", line 284, in _Popen
    return Popen(process_obj)
  File "/Users/vicentevivanco/opt/anaconda3/lib/python3.9/multiprocessing/popen_spawn_posix.py", line 32, in __init__
    super().__init__(process_obj)
  File "/Users/vicentevivanco/opt/anaconda3/lib/python3.9/multiprocessing/popen_fork.py", line 19, in __init__
    self._launch(process_obj)
  File "/Users/vicentevivanco/opt/anaconda3/lib/python3.9/multiprocessing/popen_spawn_posix.py", line 42, in _launch
    prep_data = spawn.get_preparation_data(process_obj._name)
  File "/Users/vicentevivanco/opt/anaconda3/lib/python3.9/multiprocessing/spawn.py", line 154, in get_preparation_data
    _check_not_importing_main()
  File "/Users/vicentevivanco/opt/anaconda3/lib/python3.9/multiprocessing/spawn.py", line 134, in _check_not_importing_main
    raise RuntimeError('''
RuntimeError:
        An attempt has been made to start a new process before the
        current process has finished its bootstrapping phase.
        This probably means that you are not using fork to start your
        child processes and you have forgotten to use the proper idiom
        in the main module:
            if __name__ == '__main__':
                freeze_support()
                ...
        The "freeze_support()" line can be omitted if the program
        is not going to be frozen to produce an executable.
The above exception was the direct cause of the following exception:
Traceback (most recent call last):
  File "<string>", line 1, in <module>
  File "/Users/vicentevivanco/opt/anaconda3/lib/python3.9/multiprocessing/spawn.py", line 116, in spawn_main
    exitcode = _main(fd, parent_sentinel)
  File "/Users/vicentevivanco/opt/anaconda3/lib/python3.9/multiprocessing/spawn.py", line 125, in _main
    prepare(preparation_data)
  File "/Users/vicentevivanco/opt/anaconda3/lib/python3.9/multiprocessing/spawn.py", line 236, in prepare
    _fixup_main_from_path(data['init_main_from_path'])
  File "/Users/vicentevivanco/opt/anaconda3/lib/python3.9/multiprocessing/spawn.py", line 287, in _fixup_main_from_path
    main_content = runpy.run_path(main_path,
  File "/Users/vicentevivanco/opt/anaconda3/lib/python3.9/runpy.py", line 268, in run_path
    return _run_module_code(code, init_globals, run_name,
  File "/Users/vicentevivanco/opt/anaconda3/lib/python3.9/runpy.py", line 97, in _run_module_code
    _run_code(code, mod_globals, init_globals,
  File "/Users/vicentevivanco/opt/anaconda3/lib/python3.9/runpy.py", line 87, in _run_code
    exec(code, run_globals)
  File "/Users/vicentevivanco/Desktop/Research/Mathematics/NNs/main.py", line 24, in <module>
    wandb.init(project='NNs',
  File "/Users/vicentevivanco/opt/anaconda3/lib/python3.9/site-packages/wandb/sdk/wandb_init.py", line 1037, in init
    raise Exception("problem") from error_seen
Exception: problem
[34m[1mwandb[39m[22m: [32m[41mERROR[39m[49m Abnormal program exit
Traceback (most recent call last):
  File "/Users/vicentevivanco/opt/anaconda3/lib/python3.9/site-packages/wandb/sdk/wandb_init.py", line 999, in init
    run = wi.init()
  File "/Users/vicentevivanco/opt/anaconda3/lib/python3.9/site-packages/wandb/sdk/wandb_init.py", line 523, in init
    backend.ensure_launched()
  File "/Users/vicentevivanco/opt/anaconda3/lib/python3.9/site-packages/wandb/sdk/backend/backend.py", line 220, in ensure_launched
    self.wandb_process.start()
  File "/Users/vicentevivanco/opt/anaconda3/lib/python3.9/multiprocessing/process.py", line 121, in start
    self._popen = self._Popen(self)
  File "/Users/vicentevivanco/opt/anaconda3/lib/python3.9/multiprocessing/context.py", line 284, in _Popen
    return Popen(process_obj)
  File "/Users/vicentevivanco/opt/anaconda3/lib/python3.9/multiprocessing/popen_spawn_posix.py", line 32, in __init__
    super().__init__(process_obj)
  File "/Users/vicentevivanco/opt/anaconda3/lib/python3.9/multiprocessing/popen_fork.py", line 19, in __init__
    self._launch(process_obj)
  File "/Users/vicentevivanco/opt/anaconda3/lib/python3.9/multiprocessing/popen_spawn_posix.py", line 42, in _launch
    prep_data = spawn.get_preparation_data(process_obj._name)
  File "/Users/vicentevivanco/opt/anaconda3/lib/python3.9/multiprocessing/spawn.py", line 154, in get_preparation_data
    _check_not_importing_main()
  File "/Users/vicentevivanco/opt/anaconda3/lib/python3.9/multiprocessing/spawn.py", line 134, in _check_not_importing_main
    raise RuntimeError('''
RuntimeError:
        An attempt has been made to start a new process before the
        current process has finished its bootstrapping phase.
        This probably means that you are not using fork to start your
        child processes and you have forgotten to use the proper idiom
        in the main module:
            if __name__ == '__main__':
                freeze_support()
                ...
        The "freeze_support()" line can be omitted if the program
        is not going to be frozen to produce an executable.
The above exception was the direct cause of the following exception:
Traceback (most recent call last):
  File "<string>", line 1, in <module>
  File "/Users/vicentevivanco/opt/anaconda3/lib/python3.9/multiprocessing/spawn.py", line 116, in spawn_main
    exitcode = _main(fd, parent_sentinel)
  File "/Users/vicentevivanco/opt/anaconda3/lib/python3.9/multiprocessing/spawn.py", line 125, in _main
    prepare(preparation_data)
  File "/Users/vicentevivanco/opt/anaconda3/lib/python3.9/multiprocessing/spawn.py", line 236, in prepare
    _fixup_main_from_path(data['init_main_from_path'])
  File "/Users/vicentevivanco/opt/anaconda3/lib/python3.9/multiprocessing/spawn.py", line 287, in _fixup_main_from_path
    main_content = runpy.run_path(main_path,
  File "/Users/vicentevivanco/opt/anaconda3/lib/python3.9/runpy.py", line 268, in run_path
    return _run_module_code(code, init_globals, run_name,
  File "/Users/vicentevivanco/opt/anaconda3/lib/python3.9/runpy.py", line 97, in _run_module_code
    _run_code(code, mod_globals, init_globals,
  File "/Users/vicentevivanco/opt/anaconda3/lib/python3.9/runpy.py", line 87, in _run_code
    exec(code, run_globals)
  File "/Users/vicentevivanco/Desktop/Research/Mathematics/NNs/main.py", line 24, in <module>
    wandb.init(project='NNs',
  File "/Users/vicentevivanco/opt/anaconda3/lib/python3.9/site-packages/wandb/sdk/wandb_init.py", line 1037, in init
    raise Exception("problem") from error_seen
Exception: problem
[34m[1mwandb[39m[22m: [32m[41mERROR[39m[49m Abnormal program exit
Traceback (most recent call last):
  File "/Users/vicentevivanco/opt/anaconda3/lib/python3.9/site-packages/wandb/sdk/wandb_init.py", line 999, in init
[34m[1mwandb[39m[22m: [32m[41mERROR[39m[49m Abnormal program exit
Traceback (most recent call last):
  File "/Users/vicentevivanco/opt/anaconda3/lib/python3.9/site-packages/wandb/sdk/wandb_init.py", line 999, in init
    run = wi.init()
  File "/Users/vicentevivanco/opt/anaconda3/lib/python3.9/site-packages/wandb/sdk/wandb_init.py", line 523, in init
    backend.ensure_launched()
  File "/Users/vicentevivanco/opt/anaconda3/lib/python3.9/site-packages/wandb/sdk/backend/backend.py", line 220, in ensure_launched
    self.wandb_process.start()
  File "/Users/vicentevivanco/opt/anaconda3/lib/python3.9/multiprocessing/process.py", line 121, in start
    run = wi.init()
  File "/Users/vicentevivanco/opt/anaconda3/lib/python3.9/site-packages/wandb/sdk/wandb_init.py", line 523, in init
    self._popen = self._Popen(self)
  File "/Users/vicentevivanco/opt/anaconda3/lib/python3.9/multiprocessing/context.py", line 284, in _Popen
    backend.ensure_launched()
  File "/Users/vicentevivanco/opt/anaconda3/lib/python3.9/site-packages/wandb/sdk/backend/backend.py", line 220, in ensure_launched
    return Popen(process_obj)
  File "/Users/vicentevivanco/opt/anaconda3/lib/python3.9/multiprocessing/popen_spawn_posix.py", line 32, in __init__
    super().__init__(process_obj)
  File "/Users/vicentevivanco/opt/anaconda3/lib/python3.9/multiprocessing/popen_fork.py", line 19, in __init__
    self.wandb_process.start()
    self._launch(process_obj)
  File "/Users/vicentevivanco/opt/anaconda3/lib/python3.9/multiprocessing/popen_spawn_posix.py", line 42, in _launch
  File "/Users/vicentevivanco/opt/anaconda3/lib/python3.9/multiprocessing/process.py", line 121, in start
    prep_data = spawn.get_preparation_data(process_obj._name)
  File "/Users/vicentevivanco/opt/anaconda3/lib/python3.9/multiprocessing/spawn.py", line 154, in get_preparation_data
    _check_not_importing_main()
  File "/Users/vicentevivanco/opt/anaconda3/lib/python3.9/multiprocessing/spawn.py", line 134, in _check_not_importing_main
    raise RuntimeError('''
RuntimeError:
        An attempt has been made to start a new process before the
        current process has finished its bootstrapping phase.
        This probably means that you are not using fork to start your
        child processes and you have forgotten to use the proper idiom
        in the main module:
            if __name__ == '__main__':
                freeze_support()
                ...
        The "freeze_support()" line can be omitted if the program
        is not going to be frozen to produce an executable.
The above exception was the direct cause of the following exception:
Traceback (most recent call last):
  File "<string>", line 1, in <module>
  File "/Users/vicentevivanco/opt/anaconda3/lib/python3.9/multiprocessing/spawn.py", line 116, in spawn_main
    self._popen = self._Popen(self)
  File "/Users/vicentevivanco/opt/anaconda3/lib/python3.9/multiprocessing/context.py", line 284, in _Popen
    exitcode = _main(fd, parent_sentinel)
  File "/Users/vicentevivanco/opt/anaconda3/lib/python3.9/multiprocessing/spawn.py", line 125, in _main
    return Popen(process_obj)
    prepare(preparation_data)
  File "/Users/vicentevivanco/opt/anaconda3/lib/python3.9/multiprocessing/popen_spawn_posix.py", line 32, in __init__
  File "/Users/vicentevivanco/opt/anaconda3/lib/python3.9/multiprocessing/spawn.py", line 236, in prepare
    super().__init__(process_obj)
  File "/Users/vicentevivanco/opt/anaconda3/lib/python3.9/multiprocessing/popen_fork.py", line 19, in __init__
    _fixup_main_from_path(data['init_main_from_path'])
  File "/Users/vicentevivanco/opt/anaconda3/lib/python3.9/multiprocessing/spawn.py", line 287, in _fixup_main_from_path
    self._launch(process_obj)
  File "/Users/vicentevivanco/opt/anaconda3/lib/python3.9/multiprocessing/popen_spawn_posix.py", line 42, in _launch
    main_content = runpy.run_path(main_path,
  File "/Users/vicentevivanco/opt/anaconda3/lib/python3.9/runpy.py", line 268, in run_path
    prep_data = spawn.get_preparation_data(process_obj._name)
  File "/Users/vicentevivanco/opt/anaconda3/lib/python3.9/multiprocessing/spawn.py", line 154, in get_preparation_data
    return _run_module_code(code, init_globals, run_name,
  File "/Users/vicentevivanco/opt/anaconda3/lib/python3.9/runpy.py", line 97, in _run_module_code
    _run_code(code, mod_globals, init_globals,
  File "/Users/vicentevivanco/opt/anaconda3/lib/python3.9/runpy.py", line 87, in _run_code
    exec(code, run_globals)
  File "/Users/vicentevivanco/Desktop/Research/Mathematics/NNs/main.py", line 24, in <module>
    _check_not_importing_main()
  File "/Users/vicentevivanco/opt/anaconda3/lib/python3.9/multiprocessing/spawn.py", line 134, in _check_not_importing_main
    wandb.init(project='NNs',
  File "/Users/vicentevivanco/opt/anaconda3/lib/python3.9/site-packages/wandb/sdk/wandb_init.py", line 1037, in init
    raise RuntimeError('''
    raise Exception("problem") from error_seen
RuntimeError:
        An attempt has been made to start a new process before the
        current process has finished its bootstrapping phase.
        This probably means that you are not using fork to start your
        child processes and you have forgotten to use the proper idiom
        in the main module:
            if __name__ == '__main__':
                freeze_support()
                ...
        The "freeze_support()" line can be omitted if the program
        is not going to be frozen to produce an executable.Exception: problem
The above exception was the direct cause of the following exception:
Traceback (most recent call last):
  File "<string>", line 1, in <module>
  File "/Users/vicentevivanco/opt/anaconda3/lib/python3.9/multiprocessing/spawn.py", line 116, in spawn_main
    exitcode = _main(fd, parent_sentinel)
  File "/Users/vicentevivanco/opt/anaconda3/lib/python3.9/multiprocessing/spawn.py", line 125, in _main
    prepare(preparation_data)
  File "/Users/vicentevivanco/opt/anaconda3/lib/python3.9/multiprocessing/spawn.py", line 236, in prepare
    _fixup_main_from_path(data['init_main_from_path'])
  File "/Users/vicentevivanco/opt/anaconda3/lib/python3.9/multiprocessing/spawn.py", line 287, in _fixup_main_from_path
    main_content = runpy.run_path(main_path,
  File "/Users/vicentevivanco/opt/anaconda3/lib/python3.9/runpy.py", line 268, in run_path
    return _run_module_code(code, init_globals, run_name,
  File "/Users/vicentevivanco/opt/anaconda3/lib/python3.9/runpy.py", line 97, in _run_module_code
    _run_code(code, mod_globals, init_globals,
  File "/Users/vicentevivanco/opt/anaconda3/lib/python3.9/runpy.py", line 87, in _run_code
    exec(code, run_globals)
  File "/Users/vicentevivanco/Desktop/Research/Mathematics/NNs/main.py", line 24, in <module>
    wandb.init(project='NNs',
  File "/Users/vicentevivanco/opt/anaconda3/lib/python3.9/site-packages/wandb/sdk/wandb_init.py", line 1037, in init
    raise Exception("problem") from error_seen
Exception: problem
[34m[1mwandb[39m[22m: [32m[41mERROR[39m[49m Abnormal program exit
Traceback (most recent call last):
  File "/Users/vicentevivanco/opt/anaconda3/lib/python3.9/site-packages/wandb/sdk/wandb_init.py", line 999, in init
    run = wi.init()
  File "/Users/vicentevivanco/opt/anaconda3/lib/python3.9/site-packages/wandb/sdk/wandb_init.py", line 523, in init
    backend.ensure_launched()
  File "/Users/vicentevivanco/opt/anaconda3/lib/python3.9/site-packages/wandb/sdk/backend/backend.py", line 220, in ensure_launched
    self.wandb_process.start()
  File "/Users/vicentevivanco/opt/anaconda3/lib/python3.9/multiprocessing/process.py", line 121, in start
    self._popen = self._Popen(self)
  File "/Users/vicentevivanco/opt/anaconda3/lib/python3.9/multiprocessing/context.py", line 284, in _Popen
    return Popen(process_obj)
  File "/Users/vicentevivanco/opt/anaconda3/lib/python3.9/multiprocessing/popen_spawn_posix.py", line 32, in __init__
    super().__init__(process_obj)
  File "/Users/vicentevivanco/opt/anaconda3/lib/python3.9/multiprocessing/popen_fork.py", line 19, in __init__
    self._launch(process_obj)
  File "/Users/vicentevivanco/opt/anaconda3/lib/python3.9/multiprocessing/popen_spawn_posix.py", line 42, in _launch
    prep_data = spawn.get_preparation_data(process_obj._name)
  File "/Users/vicentevivanco/opt/anaconda3/lib/python3.9/multiprocessing/spawn.py", line 154, in get_preparation_data
    _check_not_importing_main()
  File "/Users/vicentevivanco/opt/anaconda3/lib/python3.9/multiprocessing/spawn.py", line 134, in _check_not_importing_main
    raise RuntimeError('''
RuntimeError:
        An attempt has been made to start a new process before the
        current process has finished its bootstrapping phase.
        This probably means that you are not using fork to start your
        child processes and you have forgotten to use the proper idiom
        in the main module:
            if __name__ == '__main__':
                freeze_support()
                ...
        The "freeze_support()" line can be omitted if the program
        is not going to be frozen to produce an executable.
The above exception was the direct cause of the following exception:
Traceback (most recent call last):
  File "<string>", line 1, in <module>
  File "/Users/vicentevivanco/opt/anaconda3/lib/python3.9/multiprocessing/spawn.py", line 116, in spawn_main
    exitcode = _main(fd, parent_sentinel)
  File "/Users/vicentevivanco/opt/anaconda3/lib/python3.9/multiprocessing/spawn.py", line 125, in _main
    prepare(preparation_data)
  File "/Users/vicentevivanco/opt/anaconda3/lib/python3.9/multiprocessing/spawn.py", line 236, in prepare
    _fixup_main_from_path(data['init_main_from_path'])
  File "/Users/vicentevivanco/opt/anaconda3/lib/python3.9/multiprocessing/spawn.py", line 287, in _fixup_main_from_path
    main_content = runpy.run_path(main_path,
  File "/Users/vicentevivanco/opt/anaconda3/lib/python3.9/runpy.py", line 268, in run_path
    return _run_module_code(code, init_globals, run_name,
  File "/Users/vicentevivanco/opt/anaconda3/lib/python3.9/runpy.py", line 97, in _run_module_code
    _run_code(code, mod_globals, init_globals,
  File "/Users/vicentevivanco/opt/anaconda3/lib/python3.9/runpy.py", line 87, in _run_code
    exec(code, run_globals)
  File "/Users/vicentevivanco/Desktop/Research/Mathematics/NNs/main.py", line 24, in <module>
    wandb.init(project='NNs',
  File "/Users/vicentevivanco/opt/anaconda3/lib/python3.9/site-packages/wandb/sdk/wandb_init.py", line 1037, in init
    raise Exception("problem") from error_seen
Exception: problem
[34m[1mwandb[39m[22m: [32m[41mERROR[39m[49m Abnormal program exit
Traceback (most recent call last):
  File "/Users/vicentevivanco/opt/anaconda3/lib/python3.9/site-packages/wandb/sdk/wandb_init.py", line 999, in init
    run = wi.init()
  File "/Users/vicentevivanco/opt/anaconda3/lib/python3.9/site-packages/wandb/sdk/wandb_init.py", line 523, in init
    backend.ensure_launched()
  File "/Users/vicentevivanco/opt/anaconda3/lib/python3.9/site-packages/wandb/sdk/backend/backend.py", line 220, in ensure_launched
    self.wandb_process.start()
  File "/Users/vicentevivanco/opt/anaconda3/lib/python3.9/multiprocessing/process.py", line 121, in start
    self._popen = self._Popen(self)
  File "/Users/vicentevivanco/opt/anaconda3/lib/python3.9/multiprocessing/context.py", line 284, in _Popen
    return Popen(process_obj)
  File "/Users/vicentevivanco/opt/anaconda3/lib/python3.9/multiprocessing/popen_spawn_posix.py", line 32, in __init__
    super().__init__(process_obj)
  File "/Users/vicentevivanco/opt/anaconda3/lib/python3.9/multiprocessing/popen_fork.py", line 19, in __init__
    self._launch(process_obj)
  File "/Users/vicentevivanco/opt/anaconda3/lib/python3.9/multiprocessing/popen_spawn_posix.py", line 42, in _launch
    prep_data = spawn.get_preparation_data(process_obj._name)
    raise Exception("problem") from error_seen
Exception: problem
[34m[1mwandb[39m[22m: [32m[41mERROR[39m[49m Abnormal program exit
Traceback (most recent call last):
  File "/Users/vicentevivanco/opt/anaconda3/lib/python3.9/site-packages/wandb/sdk/wandb_init.py", line 999, in init
    run = wi.init()
  File "/Users/vicentevivanco/opt/anaconda3/lib/python3.9/site-packages/wandb/sdk/wandb_init.py", line 523, in init
    backend.ensure_launched()
  File "/Users/vicentevivanco/opt/anaconda3/lib/python3.9/site-packages/wandb/sdk/backend/backend.py", line 220, in ensure_launched
    self.wandb_process.start()
  File "/Users/vicentevivanco/opt/anaconda3/lib/python3.9/multiprocessing/process.py", line 121, in start
    self._popen = self._Popen(self)
  File "/Users/vicentevivanco/opt/anaconda3/lib/python3.9/multiprocessing/context.py", line 284, in _Popen
    return Popen(process_obj)
  File "/Users/vicentevivanco/opt/anaconda3/lib/python3.9/multiprocessing/popen_spawn_posix.py", line 32, in __init__
    super().__init__(process_obj)
  File "/Users/vicentevivanco/opt/anaconda3/lib/python3.9/multiprocessing/popen_fork.py", line 19, in __init__
    self._launch(process_obj)
  File "/Users/vicentevivanco/opt/anaconda3/lib/python3.9/multiprocessing/popen_spawn_posix.py", line 42, in _launch
    prep_data = spawn.get_preparation_data(process_obj._name)
  File "/Users/vicentevivanco/opt/anaconda3/lib/python3.9/multiprocessing/spawn.py", line 154, in get_preparation_data
    _check_not_importing_main()
  File "/Users/vicentevivanco/opt/anaconda3/lib/python3.9/multiprocessing/spawn.py", line 134, in _check_not_importing_main
    raise RuntimeError('''
RuntimeError:
        An attempt has been made to start a new process before the
        current process has finished its bootstrapping phase.
        This probably means that you are not using fork to start your
        child processes and you have forgotten to use the proper idiom
        in the main module:
            if __name__ == '__main__':
                freeze_support()
                ...
        The "freeze_support()" line can be omitted if the program
        is not going to be frozen to produce an executable.
The above exception was the direct cause of the following exception:
Traceback (most recent call last):
  File "<string>", line 1, in <module>
  File "/Users/vicentevivanco/opt/anaconda3/lib/python3.9/multiprocessing/spawn.py", line 116, in spawn_main
    exitcode = _main(fd, parent_sentinel)
  File "/Users/vicentevivanco/opt/anaconda3/lib/python3.9/multiprocessing/spawn.py", line 125, in _main
    prepare(preparation_data)
  File "/Users/vicentevivanco/opt/anaconda3/lib/python3.9/multiprocessing/spawn.py", line 236, in prepare
    _fixup_main_from_path(data['init_main_from_path'])
  File "/Users/vicentevivanco/opt/anaconda3/lib/python3.9/multiprocessing/spawn.py", line 287, in _fixup_main_from_path
    main_content = runpy.run_path(main_path,
  File "/Users/vicentevivanco/opt/anaconda3/lib/python3.9/runpy.py", line 268, in run_path
    return _run_module_code(code, init_globals, run_name,
  File "/Users/vicentevivanco/opt/anaconda3/lib/python3.9/runpy.py", line 97, in _run_module_code
    _run_code(code, mod_globals, init_globals,
  File "/Users/vicentevivanco/opt/anaconda3/lib/python3.9/runpy.py", line 87, in _run_code
    exec(code, run_globals)
  File "/Users/vicentevivanco/Desktop/Research/Mathematics/NNs/main.py", line 24, in <module>
    wandb.init(project='NNs',
  File "/Users/vicentevivanco/opt/anaconda3/lib/python3.9/site-packages/wandb/sdk/wandb_init.py", line 1037, in init
    raise Exception("problem") from error_seen
Exception: problem
[34m[1mwandb[39m[22m: [32m[41mERROR[39m[49m Abnormal program exit
Traceback (most recent call last):
  File "/Users/vicentevivanco/opt/anaconda3/lib/python3.9/site-packages/wandb/sdk/wandb_init.py", line 999, in init
    run = wi.init()
  File "/Users/vicentevivanco/opt/anaconda3/lib/python3.9/site-packages/wandb/sdk/wandb_init.py", line 523, in init
    backend.ensure_launched()
  File "/Users/vicentevivanco/opt/anaconda3/lib/python3.9/site-packages/wandb/sdk/backend/backend.py", line 220, in ensure_launched
    self.wandb_process.start()
  File "/Users/vicentevivanco/opt/anaconda3/lib/python3.9/multiprocessing/process.py", line 121, in start
    self._popen = self._Popen(self)
  File "/Users/vicentevivanco/opt/anaconda3/lib/python3.9/multiprocessing/context.py", line 284, in _Popen
    return Popen(process_obj)
  File "/Users/vicentevivanco/opt/anaconda3/lib/python3.9/multiprocessing/popen_spawn_posix.py", line 32, in __init__
    super().__init__(process_obj)
  File "/Users/vicentevivanco/opt/anaconda3/lib/python3.9/multiprocessing/popen_fork.py", line 19, in __init__
    self._launch(process_obj)
  File "/Users/vicentevivanco/opt/anaconda3/lib/python3.9/multiprocessing/popen_spawn_posix.py", line 42, in _launch
    prep_data = spawn.get_preparation_data(process_obj._name)
  File "/Users/vicentevivanco/opt/anaconda3/lib/python3.9/multiprocessing/spawn.py", line 154, in get_preparation_data
    _check_not_importing_main()
  File "/Users/vicentevivanco/opt/anaconda3/lib/python3.9/multiprocessing/spawn.py", line 134, in _check_not_importing_main
    raise RuntimeError('''
RuntimeError:
        An attempt has been made to start a new process before the
        current process has finished its bootstrapping phase.
        This probably means that you are not using fork to start your
        child processes and you have forgotten to use the proper idiom
        in the main module:
            if __name__ == '__main__':
                freeze_support()
                ...
        The "freeze_support()" line can be omitted if the program
        is not going to be frozen to produce an executable.
The above exception was the direct cause of the following exception:
Traceback (most recent call last):
  File "<string>", line 1, in <module>
  File "/Users/vicentevivanco/opt/anaconda3/lib/python3.9/multiprocessing/spawn.py", line 116, in spawn_main
    exitcode = _main(fd, parent_sentinel)
  File "/Users/vicentevivanco/opt/anaconda3/lib/python3.9/multiprocessing/spawn.py", line 125, in _main
    prepare(preparation_data)
  File "/Users/vicentevivanco/opt/anaconda3/lib/python3.9/multiprocessing/spawn.py", line 236, in prepare
    _fixup_main_from_path(data['init_main_from_path'])
  File "/Users/vicentevivanco/opt/anaconda3/lib/python3.9/multiprocessing/spawn.py", line 287, in _fixup_main_from_path
    main_content = runpy.run_path(main_path,
  File "/Users/vicentevivanco/opt/anaconda3/lib/python3.9/runpy.py", line 268, in run_path
    return _run_module_code(code, init_globals, run_name,
  File "/Users/vicentevivanco/opt/anaconda3/lib/python3.9/runpy.py", line 97, in _run_module_code
    _run_code(code, mod_globals, init_globals,
  File "/Users/vicentevivanco/opt/anaconda3/lib/python3.9/runpy.py", line 87, in _run_code
    exec(code, run_globals)
  File "/Users/vicentevivanco/Desktop/Research/Mathematics/NNs/main.py", line 24, in <module>
    wandb.init(project='NNs',
  File "/Users/vicentevivanco/opt/anaconda3/lib/python3.9/site-packages/wandb/sdk/wandb_init.py", line 1037, in init
    raise Exception("problem") from error_seen
Exception: problem
  0% 0/32 [00:10<?, ?it/s]
Traceback (most recent call last):
  File "/Users/vicentevivanco/opt/anaconda3/lib/python3.9/site-packages/torch/utils/data/dataloader.py", line 1011, in _try_get_data
    data = self._data_queue.get(timeout=timeout)
  File "/Users/vicentevivanco/opt/anaconda3/lib/python3.9/multiprocessing/queues.py", line 113, in get
    if not self._poll(timeout):
  File "/Users/vicentevivanco/opt/anaconda3/lib/python3.9/multiprocessing/connection.py", line 262, in poll
    return self._poll(timeout)
  File "/Users/vicentevivanco/opt/anaconda3/lib/python3.9/multiprocessing/connection.py", line 429, in _poll
    r = wait([self], timeout)
  File "/Users/vicentevivanco/opt/anaconda3/lib/python3.9/multiprocessing/connection.py", line 936, in wait
    ready = selector.select(timeout)
  File "/Users/vicentevivanco/opt/anaconda3/lib/python3.9/selectors.py", line 416, in select
    fd_event_list = self._selector.poll(timeout)
  File "/Users/vicentevivanco/opt/anaconda3/lib/python3.9/site-packages/torch/utils/data/_utils/signal_handling.py", line 66, in handler
    _error_if_any_worker_fails()
RuntimeError: DataLoader worker (pid 9071) exited unexpectedly with exit code 1. Details are lost due to multiprocessing. Rerunning with num_workers=0 may give better error trace.
The above exception was the direct cause of the following exception:
Traceback (most recent call last):
  File "/Users/vicentevivanco/Desktop/Research/Mathematics/NNs/main.py", line 53, in <module>
    loss = train(train_dataloader=train_dataloader, model=model, model_name=model_name, criterion=criterion, optimizer=optimizer, opt=opt, epoch=epoch)
  File "/Users/vicentevivanco/Desktop/Research/Mathematics/NNs/train_and_eval.py", line 37, in train
    for i ,(X, y) in bar:
  File "/Users/vicentevivanco/opt/anaconda3/lib/python3.9/site-packages/tqdm/std.py", line 1195, in __iter__
    for obj in iterable:
  File "/Users/vicentevivanco/opt/anaconda3/lib/python3.9/site-packages/torch/utils/data/dataloader.py", line 530, in __next__
    data = self._next_data()
  File "/Users/vicentevivanco/opt/anaconda3/lib/python3.9/site-packages/torch/utils/data/dataloader.py", line 1207, in _next_data
    idx, data = self._get_data()
  File "/Users/vicentevivanco/opt/anaconda3/lib/python3.9/site-packages/torch/utils/data/dataloader.py", line 1173, in _get_data
    success, data = self._try_get_data()
  File "/Users/vicentevivanco/opt/anaconda3/lib/python3.9/site-packages/torch/utils/data/dataloader.py", line 1024, in _try_get_data
    raise RuntimeError('DataLoader worker (pid(s) {}) exited unexpectedly'.format(pids_str)) from e
RuntimeError: DataLoader worker (pid(s) 9071) exited unexpectedly
  File "/Users/vicentevivanco/opt/anaconda3/lib/python3.9/site-packages/wandb/sdk/wandb_init.py", line 1037, in init
  File "/Users/vicentevivanco/opt/anaconda3/lib/python3.9/site-packages/wandb/sdk/wandb_init.py", line 1037, in init