2022-06-27 11:35:58,520 INFO    MainThread:16982 [internal.py:wandb_internal():90] W&B internal server running at pid: 16982, started at: 2022-06-27 11:35:58.520292
2022-06-27 11:35:58,522 INFO    WriterThread:16982 [datastore.py:open_for_write():75] open: /Users/vicentevivanco/Desktop/Research/Mathematics/NNs/wandb/run-20220627_113556-3tuman08/run-3tuman08.wandb
2022-06-27 11:35:58,524 DEBUG   SenderThread:16982 [sender.py:send():235] send: header
2022-06-27 11:35:58,524 DEBUG   SenderThread:16982 [sender.py:send():235] send: run
2022-06-27 11:36:01,881 ERROR   SenderThread:16982 [retry.py:__call__():126] Retry attempt failed:
Traceback (most recent call last):
  File "/Users/vicentevivanco/opt/anaconda3/lib/python3.9/site-packages/urllib3/connection.py", line 174, in _new_conn
    conn = connection.create_connection(
  File "/Users/vicentevivanco/opt/anaconda3/lib/python3.9/site-packages/urllib3/util/connection.py", line 72, in create_connection
    for res in socket.getaddrinfo(host, port, family, socket.SOCK_STREAM):
  File "/Users/vicentevivanco/opt/anaconda3/lib/python3.9/socket.py", line 954, in getaddrinfo
    for res in _socket.getaddrinfo(host, port, family, type, proto, flags):
socket.gaierror: [Errno 8] nodename nor servname provided, or not known

During handling of the above exception, another exception occurred:

Traceback (most recent call last):
  File "/Users/vicentevivanco/opt/anaconda3/lib/python3.9/site-packages/urllib3/connectionpool.py", line 703, in urlopen
    httplib_response = self._make_request(
  File "/Users/vicentevivanco/opt/anaconda3/lib/python3.9/site-packages/urllib3/connectionpool.py", line 386, in _make_request
    self._validate_conn(conn)
  File "/Users/vicentevivanco/opt/anaconda3/lib/python3.9/site-packages/urllib3/connectionpool.py", line 1040, in _validate_conn
    conn.connect()
  File "/Users/vicentevivanco/opt/anaconda3/lib/python3.9/site-packages/urllib3/connection.py", line 358, in connect
    self.sock = conn = self._new_conn()
  File "/Users/vicentevivanco/opt/anaconda3/lib/python3.9/site-packages/urllib3/connection.py", line 186, in _new_conn
    raise NewConnectionError(
urllib3.exceptions.NewConnectionError: <urllib3.connection.HTTPSConnection object at 0x7fd780c290d0>: Failed to establish a new connection: [Errno 8] nodename nor servname provided, or not known

During handling of the above exception, another exception occurred:

Traceback (most recent call last):
  File "/Users/vicentevivanco/opt/anaconda3/lib/python3.9/site-packages/requests/adapters.py", line 440, in send
    resp = conn.urlopen(
  File "/Users/vicentevivanco/opt/anaconda3/lib/python3.9/site-packages/urllib3/connectionpool.py", line 785, in urlopen
    retries = retries.increment(
  File "/Users/vicentevivanco/opt/anaconda3/lib/python3.9/site-packages/urllib3/util/retry.py", line 592, in increment
    raise MaxRetryError(_pool, url, error or ResponseError(cause))
urllib3.exceptions.MaxRetryError: HTTPSConnectionPool(host='api.wandb.ai', port=443): Max retries exceeded with url: /graphql (Caused by NewConnectionError('<urllib3.connection.HTTPSConnection object at 0x7fd780c290d0>: Failed to establish a new connection: [Errno 8] nodename nor servname provided, or not known'))

During handling of the above exception, another exception occurred:

Traceback (most recent call last):
  File "/Users/vicentevivanco/opt/anaconda3/lib/python3.9/site-packages/wandb/sdk/lib/retry.py", line 102, in __call__
    result = self._call_fn(*args, **kwargs)
  File "/Users/vicentevivanco/opt/anaconda3/lib/python3.9/site-packages/wandb/sdk/internal/internal_api.py", line 140, in execute
    return self.client.execute(*args, **kwargs)
  File "/Users/vicentevivanco/opt/anaconda3/lib/python3.9/site-packages/wandb/vendor/gql-0.2.0/wandb_gql/client.py", line 52, in execute
    result = self._get_result(document, *args, **kwargs)
  File "/Users/vicentevivanco/opt/anaconda3/lib/python3.9/site-packages/wandb/vendor/gql-0.2.0/wandb_gql/client.py", line 60, in _get_result
    return self.transport.execute(document, *args, **kwargs)
  File "/Users/vicentevivanco/opt/anaconda3/lib/python3.9/site-packages/wandb/vendor/gql-0.2.0/wandb_gql/transport/requests.py", line 38, in execute
    request = requests.post(self.url, **post_args)
  File "/Users/vicentevivanco/opt/anaconda3/lib/python3.9/site-packages/requests/api.py", line 117, in post
    return request('post', url, data=data, json=json, **kwargs)
  File "/Users/vicentevivanco/opt/anaconda3/lib/python3.9/site-packages/requests/api.py", line 61, in request
    return session.request(method=method, url=url, **kwargs)
  File "/Users/vicentevivanco/opt/anaconda3/lib/python3.9/site-packages/requests/sessions.py", line 529, in request
    resp = self.send(prep, **send_kwargs)
  File "/Users/vicentevivanco/opt/anaconda3/lib/python3.9/site-packages/requests/sessions.py", line 645, in send
    r = adapter.send(request, **kwargs)
  File "/Users/vicentevivanco/opt/anaconda3/lib/python3.9/site-packages/requests/adapters.py", line 519, in send
    raise ConnectionError(e, request=request)
requests.exceptions.ConnectionError: HTTPSConnectionPool(host='api.wandb.ai', port=443): Max retries exceeded with url: /graphql (Caused by NewConnectionError('<urllib3.connection.HTTPSConnection object at 0x7fd780c290d0>: Failed to establish a new connection: [Errno 8] nodename nor servname provided, or not known'))
