2022-06-27 11:36:32,420 INFO    MainThread:17035 [internal.py:wandb_internal():90] W&B internal server running at pid: 17035, started at: 2022-06-27 11:36:32.420024
2022-06-27 11:36:32,421 INFO    WriterThread:17035 [datastore.py:open_for_write():75] open: /Users/vicentevivanco/Desktop/Research/Mathematics/NNs/wandb/run-20220627_113630-1kwroo8d/run-1kwroo8d.wandb
2022-06-27 11:36:32,423 DEBUG   SenderThread:17035 [sender.py:send():235] send: header
2022-06-27 11:36:32,423 DEBUG   SenderThread:17035 [sender.py:send():235] send: run
2022-06-27 11:36:35,518 ERROR   SenderThread:17035 [retry.py:__call__():126] Retry attempt failed:
Traceback (most recent call last):
  File "/Users/vicentevivanco/opt/anaconda3/lib/python3.9/site-packages/urllib3/connection.py", line 174, in _new_conn
    conn = connection.create_connection(
  File "/Users/vicentevivanco/opt/anaconda3/lib/python3.9/site-packages/urllib3/util/connection.py", line 72, in create_connection
    for res in socket.getaddrinfo(host, port, family, socket.SOCK_STREAM):
  File "/Users/vicentevivanco/opt/anaconda3/lib/python3.9/socket.py", line 954, in getaddrinfo
    for res in _socket.getaddrinfo(host, port, family, type, proto, flags):
socket.gaierror: [Errno 8] nodename nor servname provided, or not known

During handling of the above exception, another exception occurred:

Traceback (most recent call last):
  File "/Users/vicentevivanco/opt/anaconda3/lib/python3.9/site-packages/urllib3/connectionpool.py", line 703, in urlopen
    httplib_response = self._make_request(
  File "/Users/vicentevivanco/opt/anaconda3/lib/python3.9/site-packages/urllib3/connectionpool.py", line 386, in _make_request
    self._validate_conn(conn)
  File "/Users/vicentevivanco/opt/anaconda3/lib/python3.9/site-packages/urllib3/connectionpool.py", line 1040, in _validate_conn
    conn.connect()
  File "/Users/vicentevivanco/opt/anaconda3/lib/python3.9/site-packages/urllib3/connection.py", line 358, in connect
    self.sock = conn = self._new_conn()
  File "/Users/vicentevivanco/opt/anaconda3/lib/python3.9/site-packages/urllib3/connection.py", line 186, in _new_conn
    raise NewConnectionError(
urllib3.exceptions.NewConnectionError: <urllib3.connection.HTTPSConnection object at 0x7f83b0fc10d0>: Failed to establish a new connection: [Errno 8] nodename nor servname provided, or not known

During handling of the above exception, another exception occurred:

Traceback (most recent call last):
  File "/Users/vicentevivanco/opt/anaconda3/lib/python3.9/site-packages/requests/adapters.py", line 440, in send
    resp = conn.urlopen(
  File "/Users/vicentevivanco/opt/anaconda3/lib/python3.9/site-packages/urllib3/connectionpool.py", line 785, in urlopen
    retries = retries.increment(
  File "/Users/vicentevivanco/opt/anaconda3/lib/python3.9/site-packages/urllib3/util/retry.py", line 592, in increment
    raise MaxRetryError(_pool, url, error or ResponseError(cause))
urllib3.exceptions.MaxRetryError: HTTPSConnectionPool(host='api.wandb.ai', port=443): Max retries exceeded with url: /graphql (Caused by NewConnectionError('<urllib3.connection.HTTPSConnection object at 0x7f83b0fc10d0>: Failed to establish a new connection: [Errno 8] nodename nor servname provided, or not known'))

During handling of the above exception, another exception occurred:

Traceback (most recent call last):
  File "/Users/vicentevivanco/opt/anaconda3/lib/python3.9/site-packages/wandb/sdk/lib/retry.py", line 102, in __call__
    result = self._call_fn(*args, **kwargs)
  File "/Users/vicentevivanco/opt/anaconda3/lib/python3.9/site-packages/wandb/sdk/internal/internal_api.py", line 140, in execute
    return self.client.execute(*args, **kwargs)
  File "/Users/vicentevivanco/opt/anaconda3/lib/python3.9/site-packages/wandb/vendor/gql-0.2.0/wandb_gql/client.py", line 52, in execute
    result = self._get_result(document, *args, **kwargs)
  File "/Users/vicentevivanco/opt/anaconda3/lib/python3.9/site-packages/wandb/vendor/gql-0.2.0/wandb_gql/client.py", line 60, in _get_result
    return self.transport.execute(document, *args, **kwargs)
  File "/Users/vicentevivanco/opt/anaconda3/lib/python3.9/site-packages/wandb/vendor/gql-0.2.0/wandb_gql/transport/requests.py", line 38, in execute
    request = requests.post(self.url, **post_args)
  File "/Users/vicentevivanco/opt/anaconda3/lib/python3.9/site-packages/requests/api.py", line 117, in post
    return request('post', url, data=data, json=json, **kwargs)
  File "/Users/vicentevivanco/opt/anaconda3/lib/python3.9/site-packages/requests/api.py", line 61, in request
    return session.request(method=method, url=url, **kwargs)
  File "/Users/vicentevivanco/opt/anaconda3/lib/python3.9/site-packages/requests/sessions.py", line 529, in request
    resp = self.send(prep, **send_kwargs)
  File "/Users/vicentevivanco/opt/anaconda3/lib/python3.9/site-packages/requests/sessions.py", line 645, in send
    r = adapter.send(request, **kwargs)
  File "/Users/vicentevivanco/opt/anaconda3/lib/python3.9/site-packages/requests/adapters.py", line 519, in send
    raise ConnectionError(e, request=request)
requests.exceptions.ConnectionError: HTTPSConnectionPool(host='api.wandb.ai', port=443): Max retries exceeded with url: /graphql (Caused by NewConnectionError('<urllib3.connection.HTTPSConnection object at 0x7f83b0fc10d0>: Failed to establish a new connection: [Errno 8] nodename nor servname provided, or not known'))
2022-06-27 11:36:50,294 DEBUG   HandlerThread:17035 [handler.py:handle_request():141] handle_request: check_version
2022-06-27 11:36:50,296 INFO    SenderThread:17035 [dir_watcher.py:__init__():205] watching files in: /Users/vicentevivanco/Desktop/Research/Mathematics/NNs/wandb/run-20220627_113630-1kwroo8d/files
2022-06-27 11:36:50,296 INFO    SenderThread:17035 [sender.py:_start_run_threads():812] run started: 1kwroo8d with start time 1656344190
2022-06-27 11:36:50,296 DEBUG   SenderThread:17035 [sender.py:send():235] send: summary
2022-06-27 11:36:50,297 INFO    SenderThread:17035 [sender.py:_save_file():949] saving file wandb-summary.json with policy end
2022-06-27 11:36:50,297 DEBUG   SenderThread:17035 [sender.py:send_request():249] send_request: check_version
2022-06-27 11:36:50,613 DEBUG   HandlerThread:17035 [handler.py:handle_request():141] handle_request: run_start
2022-06-27 11:36:50,615 DEBUG   HandlerThread:17035 [meta.py:__init__():35] meta init
2022-06-27 11:36:50,637 DEBUG   HandlerThread:17035 [meta.py:__init__():49] meta init done
2022-06-27 11:36:50,638 DEBUG   HandlerThread:17035 [meta.py:probe():209] probe
2022-06-27 11:36:50,642 DEBUG   HandlerThread:17035 [meta.py:_setup_git():199] setup git
2022-06-27 11:36:50,666 DEBUG   HandlerThread:17035 [meta.py:_setup_git():206] setup git done
2022-06-27 11:36:50,666 DEBUG   HandlerThread:17035 [meta.py:_save_pip():53] save pip
2022-06-27 11:36:50,667 DEBUG   HandlerThread:17035 [meta.py:_save_pip():67] save pip done
2022-06-27 11:36:50,667 DEBUG   HandlerThread:17035 [meta.py:_save_conda():74] save conda
2022-06-27 11:36:51,303 INFO    Thread-7  :17035 [dir_watcher.py:_on_file_created():256] file/dir created: /Users/vicentevivanco/Desktop/Research/Mathematics/NNs/wandb/run-20220627_113630-1kwroo8d/files/wandb-summary.json
2022-06-27 11:36:51,303 INFO    Thread-7  :17035 [dir_watcher.py:_on_file_created():256] file/dir created: /Users/vicentevivanco/Desktop/Research/Mathematics/NNs/wandb/run-20220627_113630-1kwroo8d/files/requirements.txt
2022-06-27 11:36:51,303 INFO    Thread-7  :17035 [dir_watcher.py:_on_file_created():256] file/dir created: /Users/vicentevivanco/Desktop/Research/Mathematics/NNs/wandb/run-20220627_113630-1kwroo8d/files/conda-environment.yaml
